<?xml version="1.0"?>
<robot xmlns:xacro="http://www.ros.org/wiki/xacro" name="BD1" >
    
    <xacro:include filename="$(find bd1_description)/urdf/bd1_leg.xacro"/>
    <xacro:include filename="$(find bd1_description)/urdf/bd1.gazebo"/>
        
    <xacro:property name="body_aprox_x" value="0.18"/>
    <xacro:property name="body_aprox_y" value="0.12"/>
    <xacro:property name="body_aprox_z" value="0.13"/>
    <xacro:property name="body_mass" value="0.5"/>
    
    <xacro:property name="head_aprox_x" value="0.29"/>
    <xacro:property name="head_aprox_y" value="0.24"/>
    <xacro:property name="head_aprox_z" value="0.1"/>
    <xacro:property name="head_mass" value="0.01"/>
    <xacro:property name="head_x_offset" value="-0.05"/>
    <xacro:property name="head_z_offset" value="0.1"/>
    
    
    <!--
    COMMON
    -->
    <xacro:macro name="servtransmission" params="joint">
        <transmission name="${joint}_transm">
            <type>transmission_interface/SimpleTransmission</type>
            <joint name="${joint}">
                <hardwareInterface>hardware_interface/PositionJointInterface</hardwareInterface>
            </joint>
            <actuator name="${joint}_motor">
                <hardwareInterface>hardware_interface/PositionActuatorInterface</hardwareInterface>
            </actuator>
        </transmission>
    </xacro:macro> 
    
    <link name="base_link">
    </link>        
        
    
    
    <!--
        BODY
    -->
    <link name="body_link">
        <visual>
            <geometry>
                <mesh filename="file://$(find bd1_description)/mesh/body_m.dae"/> 
                <!--<box size="${body_aprox_x} ${body_aprox_y} ${body_aprox_z}"/>-->
            </geometry>
            <material name="white">
                <color rgba="1 1 1 1"/>
            </material>
        </visual>
        
        <collision>
            <origin xyz="-0.015 0 0.005" rpy=" 0 0 0"/>
            <geometry>                                
                <box size="${body_aprox_x} ${body_aprox_y} ${body_aprox_z}"/>
            </geometry>
        </collision>
        
        <inertial>
            <mass value="${body_mass}"/>            
            <inertia
                ixx="${0.08*body_mass*(body_aprox_y*body_aprox_y+body_aprox_z*body_aprox_z)}" ixy="0" ixz="0"
                iyy="${0.08*body_mass*(body_aprox_x*body_aprox_x+body_aprox_z*body_aprox_z)}" iyz="0"
                izz="${0.08*body_mass*(body_aprox_x*body_aprox_x+body_aprox_y*body_aprox_y)}"
            />

        </inertial>
    </link>
    
    <joint name="body_j" type="fixed">
        <parent link="base_link"/>
        <child link="body_link"/>
        
        <origin xyz="0 0 0" rpy="0 0 0"/>
    </joint>
    
    <!--
        NECK
    -->
    
    <link name="neck_link">
        
    </link>
    
    <joint name="neck_j" type="revolute">
        <parent link="body_link"/>
        <child link="neck_link"/>
        
        <origin xyz="0.02 0 0.02" rpy="0 0 0"/>
        <limit effort="3000" velocity="0.1" lower="${-pi/2}" upper="${pi/2}"/>
        <axis xyz="0 1 0"/>
    </joint>
    
    <xacro:servtransmission joint="neck_j"/>
    
    <!--
        HEAD
    -->
    <link name="head_link">
        <visual>
            <geometry>
                <mesh filename="file://$(find bd1_description)/mesh/head_m.dae"/>                
                <!--<box size="${head_aprox_x} ${head_aprox_y} ${head_aprox_z}"/>-->
            </geometry>            
            <material name="white">
                <color rgba="1 1 1 1"/>
            </material>
        </visual>
        
        <collision>
            <origin xyz="0.04 0 0.07" rpy=" 0 0 0"/>
            <geometry>                
                <box size="${head_aprox_x} ${head_aprox_y} ${head_aprox_z}"/>
            </geometry>
        </collision>
        
        <inertial>
            <mass value="${head_mass}"/>
            <inertia
                ixx="${0.08*head_mass*(head_aprox_y*head_aprox_y+head_aprox_z*head_aprox_z)}" ixy="0" ixz="0"
                iyy="${0.08*head_mass*(head_aprox_x*head_aprox_x+head_aprox_z*head_aprox_z)}" iyz="0"
                izz="${0.08*head_mass*(head_aprox_x*head_aprox_x+head_aprox_y*head_aprox_y)}"
            />
        </inertial>
    </link>
    
    <joint name="head_j" type="fixed">
        <parent link="neck_link"/>
        <child link="head_link"/>
        
        <origin xyz="0 0 ${head_z_offset}" rpy="0 0 0"/>
    </joint>
    
    <!--
        LEGS
    -->
    <xacro:bd1_leg side="r" y_mul="-1"/>
    <xacro:bd1_leg side="l" y_mul="1"/>
    
    
    
</robot>
